Workbook

Sheet Bilhete
A1: MONTAGEM DE BILHETE — 1 bilhete, até 4 jogos | BC1: _mercados | BD1: _escopos | BE1: _chaves
A2: amarelo = você digita · azul = cálculo. Preencha SÓ os jogos que a estratégia usar (1 a 4). %Modelo = probabilidade da SELEÇÃO acontecer (não a do lado contrário). | BC2: Gols | BD2: total | BE2: gols
A3: Resultado combinado de todos os jogos preenchidos: aba ► Resumo do Bilhete | BC3: Gols 1º Tempo | BD3: casa | BE3: gols_1t
A4: DADOS DO BILHETE (uma vez — vale para todos os jogos) | BC4: Gols 2º Tempo | BD4: fora | BE4: gols_2t
A5: Casa: | B5: Superbet | C5: ID aposta | D5: #BW9V | E5: Data: | F5: 46277 | G5: Stake (R$): | H5: 2.68 | I5: Estratégia: | J5: alavancagem | K5: Estratégia = mão fixa / soros / soros parcial / gale / alavancagem — só registro, não entra na conta | BC5: Escanteios | BD5: ambas | BE5: escanteios
BC6: Escanteios 1º Tempo | BE6: escanteios_1t
A7: JOGO 1 | B7: Confronto: | C7: Botafogo-RJ x RB Bragantino | I7: Campeonato: | K7: Brasileirão Série A | BC7: Escanteios 2º Tempo | BE7: escanteios_2t
A8: Odd Criar Aposta (SGP) → | D8: 1.35 | E8: Joint Simulador (0–1, opcional) → | H8: ← cole a odd combinada que a casa mostra pro bet builder DESTE jogo | BC8: Cartões | BE8: cartoes
A9: MERCADO | B9: LINHA | C9: SELEÇÃO | D9: Odd Justa | E9: Odd Casa | F9: Odd Oposta | G9: %Modelo | H9: p usada | I9: q limpa | J9: p̂ ajust. | K9: impl. c/ margem | L9: margem linha | M9: edge | N9: edge ajust. | O9: discord. | P9: risco | Q9: check | R9: chave | S9: escopo/arg | BC9: Cartões 1º Tempo | BE9: cartoes_1t
A10: Escanteios | B10: 6.5 | C10: over | D10: 1.12 | E10: 1.1 | F10: 6.3 | G10: 0.89 | H10: =IF(N(G10)>0,G10,IF(N(D10)>0,1/D10,"")) -> 0.89 | I10: =IF(N(E10)=0,"",IF(N(F10)>=Parametros!$B$3,(1/E10)/((1/E10)+(1/F10)),1/E10)) -> 0.85135135 | J10: =IF(OR(H10="",I10=""),"",I10+Parametros!$B$4*(H10-I10)) -> 0.87840541 | K10: =IF(N(E10)=0,"",1/E10) -> 0.90909091 | L10: =IF(OR(N(E10)=0,N(F10)=0),"",1/E10+1/F10-1) -> 0.067821068 | M10: =IF(OR(H10="",N(E10)=0),"",H10*E10-1) -> -0.021 | N10: =IF(OR(J10="",N(E10)=0),"",J10*E10-1) -> -0.033754054 | O10: =IF(OR(H10="",I10=""),"",H10-I10) -> 0.038648649 | P10: =IF(O10="","",IF(ABS(O10)>0.1,"ALTA",IF(ABS(O10)>0.05,"média",""))) | Q10: =IF(AND(N(D10)>0,N(G10)>0),IF(ABS(1/D10-G10)>0.01,"D≠G ⚠","ok"),"") -> ok | R10: escanteios | S10: total | BC10: Cartões 2º Tempo | BE10: cartoes_2t
A11: Gols | B11: 0.5 | C11: over | D11: 1.22 | E11: 1.22 | F11: 4 | G11: 0.82 | H11: =IF(N(G11)>0,G11,IF(N(D11)>0,1/D11,"")) -> 0.82 | I11: =IF(N(E11)=0,"",IF(N(F11)>=Parametros!$B$3,(1/E11)/((1/E11)+(1/F11)),1/E11)) -> 0.76628352 | J11: =IF(OR(H11="",I11=""),"",I11+Parametros!$B$4*(H11-I11)) -> 0.80388506 | K11: =IF(N(E11)=0,"",1/E11) -> 0.81967213 | L11: =IF(OR(N(E11)=0,N(F11)=0),"",1/E11+1/F11-1) -> 0.069672131 | M11: =IF(OR(H11="",N(E11)=0),"",H11*E11-1) -> 0.0004 | N11: =IF(OR(J11="",N(E11)=0),"",J11*E11-1) -> -0.01926023 | O11: =IF(OR(H11="",I11=""),"",H11-I11) -> 0.053716475 | P11: =IF(O11="","",IF(ABS(O11)>0.1,"ALTA",IF(ABS(O11)>0.05,"média",""))) -> média | Q11: =IF(AND(N(D11)>0,N(G11)>0),IF(ABS(1/D11-G11)>0.01,"D≠G ⚠","ok"),"") -> ok | R11: gols | S11: casa | BC11: Cartões Vermelhos | BE11: cartoes_vermelhos
H12: =IF(N(G12)>0,G12,IF(N(D12)>0,1/D12,"")) | I12: =IF(N(E12)=0,"",IF(N(F12)>=Parametros!$B$3,(1/E12)/((1/E12)+(1/F12)),1/E12)) | J12: =IF(OR(H12="",I12=""),"",I12+Parametros!$B$4*(H12-I12)) | K12: =IF(N(E12)=0,"",1/E12) | L12: =IF(OR(N(E12)=0,N(F12)=0),"",1/E12+1/F12-1) | M12: =IF(OR(H12="",N(E12)=0),"",H12*E12-1) | N12: =IF(OR(J12="",N(E12)=0),"",J12*E12-1) | O12: =IF(OR(H12="",I12=""),"",H12-I12) | P12: =IF(O12="","",IF(ABS(O12)>0.1,"ALTA",IF(ABS(O12)>0.05,"média",""))) | Q12: =IF(AND(N(D12)>0,N(G12)>0),IF(ABS(1/D12-G12)>0.01,"D≠G ⚠","ok"),"") | BC12: Cartões Vermelhos 1º Tempo | BE12: cartoes_vermelhos_1t
H13: =IF(N(G13)>0,G13,IF(N(D13)>0,1/D13,"")) | I13: =IF(N(E13)=0,"",IF(N(F13)>=Parametros!$B$3,(1/E13)/((1/E13)+(1/F13)),1/E13)) | J13: =IF(OR(H13="",I13=""),"",I13+Parametros!$B$4*(H13-I13)) | K13: =IF(N(E13)=0,"",1/E13) | L13: =IF(OR(N(E13)=0,N(F13)=0),"",1/E13+1/F13-1) | M13: =IF(OR(H13="",N(E13)=0),"",H13*E13-1) | N13: =IF(OR(J13="",N(E13)=0),"",J13*E13-1) | O13: =IF(OR(H13="",I13=""),"",H13-I13) | P13: =IF(O13="","",IF(ABS(O13)>0.1,"ALTA",IF(ABS(O13)>0.05,"média",""))) | Q13: =IF(AND(N(D13)>0,N(G13)>0),IF(ABS(1/D13-G13)>0.01,"D≠G ⚠","ok"),"") | BC13: Cartões Vermelhos 2º Tempo | BE13: cartoes_vermelhos_2t
H14: =IF(N(G14)>0,G14,IF(N(D14)>0,1/D14,"")) | I14: =IF(N(E14)=0,"",IF(N(F14)>=Parametros!$B$3,(1/E14)/((1/E14)+(1/F14)),1/E14)) | J14: =IF(OR(H14="",I14=""),"",I14+Parametros!$B$4*(H14-I14)) | K14: =IF(N(E14)=0,"",1/E14) | L14: =IF(OR(N(E14)=0,N(F14)=0),"",1/E14+1/F14-1) | M14: =IF(OR(H14="",N(E14)=0),"",H14*E14-1) | N14: =IF(OR(J14="",N(E14)=0),"",J14*E14-1) | O14: =IF(OR(H14="",I14=""),"",H14-I14) | P14: =IF(O14="","",IF(ABS(O14)>0.1,"ALTA",IF(ABS(O14)>0.05,"média",""))) | Q14: =IF(AND(N(D14)>0,N(G14)>0),IF(ABS(1/D14-G14)>0.01,"D≠G ⚠","ok"),"") | BC14: Finalizações | BE14: chutes
H15: =IF(N(G15)>0,G15,IF(N(D15)>0,1/D15,"")) | I15: =IF(N(E15)=0,"",IF(N(F15)>=Parametros!$B$3,(1/E15)/((1/E15)+(1/F15)),1/E15)) | J15: =IF(OR(H15="",I15=""),"",I15+Parametros!$B$4*(H15-I15)) | K15: =IF(N(E15)=0,"",1/E15) | L15: =IF(OR(N(E15)=0,N(F15)=0),"",1/E15+1/F15-1) | M15: =IF(OR(H15="",N(E15)=0),"",H15*E15-1) | N15: =IF(OR(J15="",N(E15)=0),"",J15*E15-1) | O15: =IF(OR(H15="",I15=""),"",H15-I15) | P15: =IF(O15="","",IF(ABS(O15)>0.1,"ALTA",IF(ABS(O15)>0.05,"média",""))) | Q15: =IF(AND(N(D15)>0,N(G15)>0),IF(ABS(1/D15-G15)>0.01,"D≠G ⚠","ok"),"") | BC15: Finalizações 1º Tempo | BE15: chutes_1t
H16: =IF(N(G16)>0,G16,IF(N(D16)>0,1/D16,"")) | I16: =IF(N(E16)=0,"",IF(N(F16)>=Parametros!$B$3,(1/E16)/((1/E16)+(1/F16)),1/E16)) | J16: =IF(OR(H16="",I16=""),"",I16+Parametros!$B$4*(H16-I16)) | K16: =IF(N(E16)=0,"",1/E16) | L16: =IF(OR(N(E16)=0,N(F16)=0),"",1/E16+1/F16-1) | M16: =IF(OR(H16="",N(E16)=0),"",H16*E16-1) | N16: =IF(OR(J16="",N(E16)=0),"",J16*E16-1) | O16: =IF(OR(H16="",I16=""),"",H16-I16) | P16: =IF(O16="","",IF(ABS(O16)>0.1,"ALTA",IF(ABS(O16)>0.05,"média",""))) | Q16: =IF(AND(N(D16)>0,N(G16)>0),IF(ABS(1/D16-G16)>0.01,"D≠G ⚠","ok"),"") | BC16: Finalizações 2º Tempo | BE16: chutes_2t
H17: =IF(N(G17)>0,G17,IF(N(D17)>0,1/D17,"")) | I17: =IF(N(E17)=0,"",IF(N(F17)>=Parametros!$B$3,(1/E17)/((1/E17)+(1/F17)),1/E17)) | J17: =IF(OR(H17="",I17=""),"",I17+Parametros!$B$4*(H17-I17)) | K17: =IF(N(E17)=0,"",1/E17) | L17: =IF(OR(N(E17)=0,N(F17)=0),"",1/E17+1/F17-1) | M17: =IF(OR(H17="",N(E17)=0),"",H17*E17-1) | N17: =IF(OR(J17="",N(E17)=0),"",J17*E17-1) | O17: =IF(OR(H17="",I17=""),"",H17-I17) | P17: =IF(O17="","",IF(ABS(O17)>0.1,"ALTA",IF(ABS(O17)>0.05,"média",""))) | Q17: =IF(AND(N(D17)>0,N(G17)>0),IF(ABS(1/D17-G17)>0.01,"D≠G ⚠","ok"),"") | BC17: Finalizações no Gol | BE17: chutes_gol
A18: → JOGO 1 | B18: produto | C18: =IF(COUNT(H10:H17)=0,"",PRODUCT(H10:H17)) -> 0.7298 | D18: SGP implica | F18: =IF(N(D8)>0,1/D8,"") -> 0.74074074 | G18: JOINT USADO | I18: =IF(N(G8)>0,G8,IF(N(D8)>0,1/D8,IF(COUNT(H10:H17)=0,"",PRODUCT(H10:H17)))) -> 0.74074074 | J18: nº pernas | K18: =COUNT(H10:H17) -> 2 | L18: =IF(AND(COUNT(H10:H17)>1,N(G8)=0,N(D8)=0),"⚠ 2+ pernas do mesmo jogo sem odd final: o 'produto' está errado — "&"digite a Odd Criar Aposta em D8 (ou o Joint Simulador em G8)","") | BC18: Finalizações no Gol 1º Tempo | BE18: chutes_gol_1t
B19: Π odd casa | C19: =IF(COUNT(E10:E17)=0,"",PRODUCT(E10:E17)) -> 1.342 | D19: odd C.Aposta | F19: =IF(N(D8)>0,D8,"") -> 1.35 | G19: correlação | H19: =IF(AND(N(D8)>0,COUNT(E10:E17)>0),D8/PRODUCT(E10:E17)-1,"") -> 0.0059612519 | I19: prod. mercado | K19: =IF(COUNT(I10:I17)=0,"",PRODUCT(I10:I17)) -> 0.65237651 | L19: prod. λ-ajust. | N19: =IF(COUNT(J10:J17)=0,"",PRODUCT(J10:J17)) -> 0.70613698 | O19: correlação < 0 = casa paga MENOS que multiplicar as pernas → correlação positiva embutida. prod. mercado = Π q limpa. prod. λ-ajust. = Π p̂ ajust. | BC19: Finalizações no Gol 2º Tempo | BE19: chutes_gol_2t
BC20: Faltas | BE20: faltas
A21: JOGO 2 | B21: Confronto: | C21: Santos x Cruzeiro | I21: Campeonato: | K21: Brasileirão Série A | BC21: Faltas 1º Tempo | BE21: faltas_1t
A22: Odd Criar Aposta (SGP) → | D22: 1.55 | E22: Joint Simulador (0–1, opcional) → | H22: ← cole a odd combinada que a casa mostra pro bet builder DESTE jogo | BC22: Faltas 2º Tempo | BE22: faltas_2t
A23: MERCADO | B23: LINHA | C23: SELEÇÃO | D23: Odd Justa | E23: Odd Casa | F23: Odd Oposta | G23: %Modelo | H23: p usada | I23: q limpa | J23: p̂ ajust. | K23: impl. c/ margem | L23: margem linha | M23: edge | N23: edge ajust. | O23: discord. | P23: risco | Q23: check | R23: chave | S23: escopo/arg | BC23: Impedimentos | BE23: impedimentos
A24: Gols | B24: 1.5 | C24: over | D24: 1.16 | E24: 1.27 | F24: 3.8 | G24: 0.86 | H24: =IF(N(G24)>0,G24,IF(N(D24)>0,1/D24,"")) -> 0.86 | I24: =IF(N(E24)=0,"",IF(N(F24)>=Parametros!$B$3,(1/E24)/((1/E24)+(1/F24)),1/E24)) -> 0.7495069 | J24: =IF(OR(H24="",I24=""),"",I24+Parametros!$B$4*(H24-I24)) -> 0.82685207 | K24: =IF(N(E24)=0,"",1/E24) -> 0.78740157 | L24: =IF(OR(N(E24)=0,N(F24)=0),"",1/E24+1/F24-1) -> 0.05055947 | M24: =IF(OR(H24="",N(E24)=0),"",H24*E24-1) -> 0.0922 | N24: =IF(OR(J24="",N(E24)=0),"",J24*E24-1) -> 0.05010213 | O24: =IF(OR(H24="",I24=""),"",H24-I24) -> 0.1104931 | P24: =IF(O24="","",IF(ABS(O24)>0.1,"ALTA",IF(ABS(O24)>0.05,"média",""))) -> ALTA | Q24: =IF(AND(N(D24)>0,N(G24)>0),IF(ABS(1/D24-G24)>0.01,"D≠G ⚠","ok"),"") -> ok | R24: gols | S24: total | BC24: Impedimentos 1º Tempo | BE24: impedimentos_1t
A25: Cartões | B25: 3.5 | C25: over | D25: 1.17 | E25: 1.19 | F25: 3.85 | G25: 0.85 | H25: =IF(N(G25)>0,G25,IF(N(D25)>0,1/D25,"")) -> 0.85 | I25: =IF(N(E25)=0,"",IF(N(F25)>=Parametros!$B$3,(1/E25)/((1/E25)+(1/F25)),1/E25)) -> 0.76388889 | J25: =IF(OR(H25="",I25=""),"",I25+Parametros!$B$4*(H25-I25)) -> 0.82416667 | K25: =IF(N(E25)=0,"",1/E25) -> 0.84033613 | L25: =IF(OR(N(E25)=0,N(F25)=0),"",1/E25+1/F25-1) -> 0.10007639 | M25: =IF(OR(H25="",N(E25)=0),"",H25*E25-1) -> 0.0115 | N25: =IF(OR(J25="",N(E25)=0),"",J25*E25-1) -> -0.019241667 | O25: =IF(OR(H25="",I25=""),"",H25-I25) -> 0.086111111 | P25: =IF(O25="","",IF(ABS(O25)>0.1,"ALTA",IF(ABS(O25)>0.05,"média",""))) -> média | Q25: =IF(AND(N(D25)>0,N(G25)>0),IF(ABS(1/D25-G25)>0.01,"D≠G ⚠","ok"),"") -> ok | R25: cartoes | S25: total | BC25: Impedimentos 2º Tempo | BE25: impedimentos_2t
H26: =IF(N(G26)>0,G26,IF(N(D26)>0,1/D26,"")) | I26: =IF(N(E26)=0,"",IF(N(F26)>=Parametros!$B$3,(1/E26)/((1/E26)+(1/F26)),1/E26)) | J26: =IF(OR(H26="",I26=""),"",I26+Parametros!$B$4*(H26-I26)) | K26: =IF(N(E26)=0,"",1/E26) | L26: =IF(OR(N(E26)=0,N(F26)=0),"",1/E26+1/F26-1) | M26: =IF(OR(H26="",N(E26)=0),"",H26*E26-1) | N26: =IF(OR(J26="",N(E26)=0),"",J26*E26-1) | O26: =IF(OR(H26="",I26=""),"",H26-I26) | P26: =IF(O26="","",IF(ABS(O26)>0.1,"ALTA",IF(ABS(O26)>0.05,"média",""))) | Q26: =IF(AND(N(D26)>0,N(G26)>0),IF(ABS(1/D26-G26)>0.01,"D≠G ⚠","ok"),"") | BC26: Laterais | BE26: laterais
H27: =IF(N(G27)>0,G27,IF(N(D27)>0,1/D27,"")) | I27: =IF(N(E27)=0,"",IF(N(F27)>=Parametros!$B$3,(1/E27)/((1/E27)+(1/F27)),1/E27)) | J27: =IF(OR(H27="",I27=""),"",I27+Parametros!$B$4*(H27-I27)) | K27: =IF(N(E27)=0,"",1/E27) | L27: =IF(OR(N(E27)=0,N(F27)=0),"",1/E27+1/F27-1) | M27: =IF(OR(H27="",N(E27)=0),"",H27*E27-1) | N27: =IF(OR(J27="",N(E27)=0),"",J27*E27-1) | O27: =IF(OR(H27="",I27=""),"",H27-I27) | P27: =IF(O27="","",IF(ABS(O27)>0.1,"ALTA",IF(ABS(O27)>0.05,"média",""))) | Q27: =IF(AND(N(D27)>0,N(G27)>0),IF(ABS(1/D27-G27)>0.01,"D≠G ⚠","ok"),"") | BC27: Laterais 1º Tempo | BE27: laterais_1t
H28: =IF(N(G28)>0,G28,IF(N(D28)>0,1/D28,"")) | I28: =IF(N(E28)=0,"",IF(N(F28)>=Parametros!$B$3,(1/E28)/((1/E28)+(1/F28)),1/E28)) | J28: =IF(OR(H28="",I28=""),"",I28+Parametros!$B$4*(H28-I28)) | K28: =IF(N(E28)=0,"",1/E28) | L28: =IF(OR(N(E28)=0,N(F28)=0),"",1/E28+1/F28-1) | M28: =IF(OR(H28="",N(E28)=0),"",H28*E28-1) | N28: =IF(OR(J28="",N(E28)=0),"",J28*E28-1) | O28: =IF(OR(H28="",I28=""),"",H28-I28) | P28: =IF(O28="","",IF(ABS(O28)>0.1,"ALTA",IF(ABS(O28)>0.05,"média",""))) | Q28: =IF(AND(N(D28)>0,N(G28)>0),IF(ABS(1/D28-G28)>0.01,"D≠G ⚠","ok"),"") | BC28: Laterais 2º Tempo | BE28: laterais_2t
H29: =IF(N(G29)>0,G29,IF(N(D29)>0,1/D29,"")) | I29: =IF(N(E29)=0,"",IF(N(F29)>=Parametros!$B$3,(1/E29)/((1/E29)+(1/F29)),1/E29)) | J29: =IF(OR(H29="",I29=""),"",I29+Parametros!$B$4*(H29-I29)) | K29: =IF(N(E29)=0,"",1/E29) | L29: =IF(OR(N(E29)=0,N(F29)=0),"",1/E29+1/F29-1) | M29: =IF(OR(H29="",N(E29)=0),"",H29*E29-1) | N29: =IF(OR(J29="",N(E29)=0),"",J29*E29-1) | O29: =IF(OR(H29="",I29=""),"",H29-I29) | P29: =IF(O29="","",IF(ABS(O29)>0.1,"ALTA",IF(ABS(O29)>0.05,"média",""))) | Q29: =IF(AND(N(D29)>0,N(G29)>0),IF(ABS(1/D29-G29)>0.01,"D≠G ⚠","ok"),"") | BC29: Tiros de Meta | BE29: tiros_meta
H30: =IF(N(G30)>0,G30,IF(N(D30)>0,1/D30,"")) | I30: =IF(N(E30)=0,"",IF(N(F30)>=Parametros!$B$3,(1/E30)/((1/E30)+(1/F30)),1/E30)) | J30: =IF(OR(H30="",I30=""),"",I30+Parametros!$B$4*(H30-I30)) | K30: =IF(N(E30)=0,"",1/E30) | L30: =IF(OR(N(E30)=0,N(F30)=0),"",1/E30+1/F30-1) | M30: =IF(OR(H30="",N(E30)=0),"",H30*E30-1) | N30: =IF(OR(J30="",N(E30)=0),"",J30*E30-1) | O30: =IF(OR(H30="",I30=""),"",H30-I30) | P30: =IF(O30="","",IF(ABS(O30)>0.1,"ALTA",IF(ABS(O30)>0.05,"média",""))) | Q30: =IF(AND(N(D30)>0,N(G30)>0),IF(ABS(1/D30-G30)>0.01,"D≠G ⚠","ok"),"") | BC30: Tiros de Meta 1º Tempo | BE30: tiros_meta_1t
H31: =IF(N(G31)>0,G31,IF(N(D31)>0,1/D31,"")) | I31: =IF(N(E31)=0,"",IF(N(F31)>=Parametros!$B$3,(1/E31)/((1/E31)+(1/F31)),1/E31)) | J31: =IF(OR(H31="",I31=""),"",I31+Parametros!$B$4*(H31-I31)) | K31: =IF(N(E31)=0,"",1/E31) | L31: =IF(OR(N(E31)=0,N(F31)=0),"",1/E31+1/F31-1) | M31: =IF(OR(H31="",N(E31)=0),"",H31*E31-1) | N31: =IF(OR(J31="",N(E31)=0),"",J31*E31-1) | O31: =IF(OR(H31="",I31=""),"",H31-I31) | P31: =IF(O31="","",IF(ABS(O31)>0.1,"ALTA",IF(ABS(O31)>0.05,"média",""))) | Q31: =IF(AND(N(D31)>0,N(G31)>0),IF(ABS(1/D31-G31)>0.01,"D≠G ⚠","ok"),"") | BC31: Tiros de Meta 2º Tempo | BE31: tiros_meta_2t
A32: → JOGO 2 | B32: produto | C32: =IF(COUNT(H24:H31)=0,"",PRODUCT(H24:H31)) -> 0.731 | D32: SGP implica | F32: =IF(N(D22)>0,1/D22,"") -> 0.64516129 | G32: JOINT USADO | I32: =IF(N(G22)>0,G22,IF(N(D22)>0,1/D22,IF(COUNT(H24:H31)=0,"",PRODUCT(H24:H31)))) -> 0.64516129 | J32: nº pernas | K32: =COUNT(H24:H31) -> 2 | L32: =IF(AND(COUNT(H24:H31)>1,N(G22)=0,N(D22)=0),"⚠ 2+ pernas do mesmo jogo sem odd final: o 'produto' está errado — "&"digite a Odd Criar Aposta em D21 (ou o Joint Simulador em G21)","") | BC32: Desarmes | BE32: desarmes
B33: Π odd casa | C33: =IF(COUNT(E24:E31)=0,"",PRODUCT(E24:E31)) -> 1.5113 | D33: odd C.Aposta | F33: =IF(N(D22)>0,D22,"") -> 1.55 | G33: correlação | H33: =IF(AND(N(D22)>0,COUNT(E24:E31)>0),D22/PRODUCT(E24:E31)-1,"") -> 0.025607093 | I33: prod. mercado | K33: =IF(COUNT(I24:I31)=0,"",PRODUCT(I24:I31)) -> 0.57254 | L33: prod. λ-ajust. | N33: =IF(COUNT(J24:J31)=0,"",PRODUCT(J24:J31)) -> 0.68146392 | O33: correlação < 0 = casa paga MENOS que multiplicar as pernas → correlação positiva embutida. prod. mercado = Π q limpa. prod. λ-ajust. = Π p̂ ajust. | BC33: Desarmes 1º Tempo | BE33: desarmes_1t
BC34: Desarmes 2º Tempo | BE34: desarmes_2t
A35: JOGO 3 | B35: Confronto: | I35: Campeonato: | BC35: Defesas do Goleiro | BE35: defesas_goleiro
A36: A | E36: Joint Simulador (0–1, opcional) → | H36: ← cole a odd combinada que a casa mostra pro bet builder DESTE jogo | BC36: Defesas do Goleiro 1º Tempo | BE36: defesas_goleiro_1t
A37: MERCADO | B37: LINHA | C37: SELEÇÃO | D37: Odd Justa | E37: Odd Casa | F37: Odd Oposta | G37: %Modelo | H37: p usada | I37: q limpa | J37: p̂ ajust. | K37: impl. c/ margem | L37: margem linha | M37: edge | N37: edge ajust. | O37: discord. | P37: risco | Q37: check | R37: chave | S37: escopo/arg | BC37: Defesas do Goleiro 2º Tempo | BE37: defesas_goleiro_2t
H38: =IF(N(G38)>0,G38,IF(N(D38)>0,1/D38,"")) | I38: =IF(N(E38)=0,"",IF(N(F38)>=Parametros!$B$3,(1/E38)/((1/E38)+(1/F38)),1/E38)) | J38: =IF(OR(H38="",I38=""),"",I38+Parametros!$B$4*(H38-I38)) | K38: =IF(N(E38)=0,"",1/E38) | L38: =IF(OR(N(E38)=0,N(F38)=0),"",1/E38+1/F38-1) | M38: =IF(OR(H38="",N(E38)=0),"",H38*E38-1) | N38: =IF(OR(J38="",N(E38)=0),"",J38*E38-1) | O38: =IF(OR(H38="",I38=""),"",H38-I38) | P38: =IF(O38="","",IF(ABS(O38)>0.1,"ALTA",IF(ABS(O38)>0.05,"média",""))) | Q38: =IF(AND(N(D38)>0,N(G38)>0),IF(ABS(1/D38-G38)>0.01,"D≠G ⚠","ok"),"") | R38: escanteios | S38: total | BC38: Resultado Final | BE38: resultado
H39: =IF(N(G39)>0,G39,IF(N(D39)>0,1/D39,"")) | I39: =IF(N(E39)=0,"",IF(N(F39)>=Parametros!$B$3,(1/E39)/((1/E39)+(1/F39)),1/E39)) | J39: =IF(OR(H39="",I39=""),"",I39+Parametros!$B$4*(H39-I39)) | K39: =IF(N(E39)=0,"",1/E39) | L39: =IF(OR(N(E39)=0,N(F39)=0),"",1/E39+1/F39-1) | M39: =IF(OR(H39="",N(E39)=0),"",H39*E39-1) | N39: =IF(OR(J39="",N(E39)=0),"",J39*E39-1) | O39: =IF(OR(H39="",I39=""),"",H39-I39) | P39: =IF(O39="","",IF(ABS(O39)>0.1,"ALTA",IF(ABS(O39)>0.05,"média",""))) | Q39: =IF(AND(N(D39)>0,N(G39)>0),IF(ABS(1/D39-G39)>0.01,"D≠G ⚠","ok"),"") | R39: gols | S39: total | BC39: Resultado Final 1º Tempo | BE39: resultado_1t
H40: =IF(N(G40)>0,G40,IF(N(D40)>0,1/D40,"")) | I40: =IF(N(E40)=0,"",IF(N(F40)>=Parametros!$B$3,(1/E40)/((1/E40)+(1/F40)),1/E40)) | J40: =IF(OR(H40="",I40=""),"",I40+Parametros!$B$4*(H40-I40)) | K40: =IF(N(E40)=0,"",1/E40) | L40: =IF(OR(N(E40)=0,N(F40)=0),"",1/E40+1/F40-1) | M40: =IF(OR(H40="",N(E40)=0),"",H40*E40-1) | N40: =IF(OR(J40="",N(E40)=0),"",J40*E40-1) | O40: =IF(OR(H40="",I40=""),"",H40-I40) | P40: =IF(O40="","",IF(ABS(O40)>0.1,"ALTA",IF(ABS(O40)>0.05,"média",""))) | Q40: =IF(AND(N(D40)>0,N(G40)>0),IF(ABS(1/D40-G40)>0.01,"D≠G ⚠","ok"),"") | BC40: Resultado Final 2º Tempo | BE40: resultado_2t
...

Sheet Resumo do Bilhete
A1: RESUMO DO BILHETE
A2: Um jogo por linha (só os preenchidos entram). P(bilhete) = Π dos JOINT USADO. Casa / ID / stake vêm do cabeçalho da aba Bilhete.
A3: =IF(Bilhete!B5="","(bilhete sem casa/ID no cabeçalho)","Casa: "&Bilhete!B5&" · ID: "&Bilhete!D5&" · Stake: R$ "&TEXT(Bilhete!H5,"0.00")&" · "&Bilhete!J5) -> Casa: Superbet · ID: #BW9V · Stake: R$ 003 · alavancagem
A5: Jogo | B5: Confronto | C5: nº pernas | D5: JOINT USADO | E5: odd casa efetiva | F5: fonte do joint | G5: joint mercado | H5: joint λ-ajust.
A6: JOGO 1 | B6: =Bilhete!C7 -> Botafogo-RJ x RB Bragantino | C6: =Bilhete!K18 -> 2 | D6: =IF(Bilhete!I18="","",Bilhete!I18) -> 0.74074074 | E6: =IF(N(Bilhete!D8)>0,Bilhete!D8,IF(COUNT(Bilhete!E10:E17)=0,"",PRODUCT(Bilhete!E10:E17))) -> 1.35 | F6: =IF(N(Bilhete!G8)>0,"Simulador",IF(N(Bilhete!D8)>0,"odd final (SGP)",IF(COUNT(Bilhete!H10:H17)>1,"produto ⚠","perna única"))) -> odd final (SGP) | G6: =IF(Bilhete!K19="","",Bilhete!K19) -> 0.65237651 | H6: =IF(Bilhete!N19="","",Bilhete!N19) -> 0.70613698
A7: JOGO 2 | B7: =Bilhete!C21 -> Santos x Cruzeiro | C7: =Bilhete!K32 -> 2 | D7: =IF(Bilhete!I32="","",Bilhete!I32) -> 0.64516129 | E7: =IF(N(Bilhete!D22)>0,Bilhete!D22,IF(COUNT(Bilhete!E24:E31)=0,"",PRODUCT(Bilhete!E24:E31))) -> 1.55 | F7: =IF(N(Bilhete!G22)>0,"Simulador",IF(N(Bilhete!D22)>0,"odd final (SGP)",IF(COUNT(Bilhete!H24:H31)>1,"produto ⚠","perna única"))) -> odd final (SGP) | G7: =IF(Bilhete!K33="","",Bilhete!K33) -> 0.57254 | H7: =IF(Bilhete!N33="","",Bilhete!N33) -> 0.68146392
A8: JOGO 3 | B8: =Bilhete!C35 -> 0 | C8: =Bilhete!K46 -> 0 | D8: =IF(Bilhete!I46="","",Bilhete!I46) | E8: =IF(N(Bilhete!D36)>0,Bilhete!D36,IF(COUNT(Bilhete!E38:E45)=0,"",PRODUCT(Bilhete!E38:E45))) | F8: =IF(N(Bilhete!G36)>0,"Simulador",IF(N(Bilhete!D36)>0,"odd final (SGP)",IF(COUNT(Bilhete!H38:H45)>1,"produto ⚠","perna única"))) -> perna única | G8: =IF(Bilhete!K47="","",Bilhete!K47) | H8: =IF(Bilhete!N47="","",Bilhete!N47)
A9: JOGO 4 | B9: =Bilhete!C49 -> 0 | C9: =Bilhete!K60 -> 0 | D9: =IF(Bilhete!I60="","",Bilhete!I60) | E9: =IF(N(Bilhete!D50)>0,Bilhete!D50,IF(COUNT(Bilhete!E52:E59)=0,"",PRODUCT(Bilhete!E52:E59))) | F9: =IF(N(Bilhete!G50)>0,"Simulador",IF(N(Bilhete!D50)>0,"odd final (SGP)",IF(COUNT(Bilhete!H52:H59)>1,"produto ⚠","perna única"))) -> perna única | G9: =IF(Bilhete!K61="","",Bilhete!K61) | H9: =IF(Bilhete!N61="","",Bilhete!N61)
A11: Nº de jogos no bilhete | B11: =COUNT(D6:D9) -> 2
A12: P(bilhete) = Π joint usado | B12: =IF(COUNT(D6:D9)=0,"",PRODUCT(D6:D9)) -> 0.47789725 | C12: produto entre jogos (jogos ~independentes)
A13: P(bilhete) — mercado (de-vig) | B13: =IF(COUNT(G6:G9)=0,"",PRODUCT(G6:G9)) -> 0.37351165 | C13: o que a casa 'acha' — Π (q limpa) por jogo
A14: P(bilhete) — modelo (λ-ajust.) | B14: =IF(COUNT(H6:H9)=0,"",PRODUCT(H6:H9)) -> 0.48120687 | C14: Π (p̂ ajust.) por jogo — modelo encolhido pro mercado por λ
A15: Haircut de confiança (pp) | B15: 0 | C15: desconto manual — o modelo tende a ser otimista nas caudas
A16: P(bilhete) ajustado | B16: =IF(B12="","",MAX(0,B12-B15)) -> 0.47789725
A18: Odd casa do bilhete | B18: =IF(COUNT(E6:E9)=0,"",PRODUCT(E6:E9)) -> 2.0925 | C18: usa a odd Criar Aposta de cada jogo
A19: Odd se pernas independentes (Π todas) | B19: =IF(COUNT(Bilhete!E10:E17,Bilhete!E24:E31,Bilhete!E38:E45,Bilhete!E52:E59)=0,"",PRODUCT(Bilhete!E10:E17,Bilhete!E24:E31,Bilhete!E38:E45,Bilhete!E52:E59)) -> 2.0281646 | C19: multiplicar as pernas soltas. Maior que a de cima = correlação positiva precificada
A20: Margem composta embutida | B20: =IF(OR(B13="",B13=0,B19=""),"",(1/B13)/B19-1) -> 0.32005691 | C20: (1/P mercado) ÷ Odd independentes − 1 — o pedágio total
A21: Odd justa do bilhete (modelo) | B21: =IF(OR(B12="",B12=0),"",1/B12) -> 2.0925 | C21: =1 / P(bilhete) -> #NAME?
A22: Retorno se ganhar (R$) | B22: =IF(OR(B18="",Bilhete!$H$5=""),"",Bilhete!$H$5*B18) -> 5.6079 | C22: stake (cabeçalho) × odd casa do bilhete
A24: EV do bilhete | B24: =IF(OR(B12="",B18=""),"",B12*B18-1) -> 0
A25: EV ajustado (com haircut) | B25: =IF(OR(B16="",B18=""),"",B16*B18-1) -> 0 | C25: o número em que confiar mais
A26: EV (λ-ajust.) | B26: =IF(OR(B14="",B18=""),"",B14*B18-1) -> 0.0069253774 | C26: com p̂ encolhido pro mercado por λ
A27: EV se o mercado estiver certo | B27: =IF(OR(B13="",B18=""),"",B13*B18-1) -> -0.21842688 | C27: ≈ −(margem composta). O que se perde no longo prazo sem edge real
A28: P(pelo menos 1 jogo falha) | B28: =IF(B12="","",1-B12) -> 0.52210275
A29: Kelly sugerido (% da banca) | B29: =IF(OR(B16="",B18="",B18<=1),"",Parametros!$B$2*MAX(0,B16*B18-1)/(B18-1)) -> 0 | C29: 0% se o EV ajustado não for positivo. Teto, não alvo.
A31: CHECAGENS
A32: Combinação ≥ 60%? | B32: =IF(B16="","",IF(B16>=0.6,"sim","NÃO")) -> NÃO
A33: Combinação ≥ 80%? | B33: =IF(B16="","",IF(B16>=0.8,"sim","NÃO")) -> NÃO
A34: Nº de jogos | B34: =IF(COUNT(D6:D9)>=3,"⚠ 3+ jogos: a margem se acumula por jogo — EV real abaixo do calculado","ok") -> ok
A35: Joint por jogo | B35: =IF(COUNTIF(F6:F9,"produto ⚠")>0,"⚠ algum jogo com 2+ pernas sem odd Criar Aposta — digite a odd","ok") -> ok
A36: Discordância das pernas | B36: =IF(COUNTIF(Bilhete!P1:P60,"ALTA")>0,"⚠ há perna com discordância >10pp — risco, não valor (ver aba Bilhete)","ok") -> ⚠ há perna com discordância >10pp — risco, não valor (ver aba Bilhete)
A37: Cabeçalho do bilhete | B37: =IF(OR(Bilhete!B5="",Bilhete!D5="",Bilhete!H5=""),"⚠ preencha Casa / ID / Stake no topo da aba Bilhete antes de exportar","ok") -> ok
A40: JOINT USADO por jogo, na ordem: 1º Joint Simulador · 2º 1/Odd Criar Aposta · 3º produto dos %Modelo.
A41: O 3º só vale pra perna única — com 2+ pernas do mesmo jogo SUPER ou SUBESTIMA.
A43: 1 bilhete = os jogos preenchidos. Para registrar no warlock_tracker: python tracking/exportar_para_tracker.py

Sheet Poisson
A1: POISSON / BIN. NEGATIVA — de onde vem o '~90%'
A2: Dado o ESPERADO do mercado (μ), calcula a probabilidade de cada linha. É a etapa que core/models/contagem.py faz internamente; aqui é pra conferir à mão e achar o %Modelo de uma perna.
A4: μ — esperado do mercado | B4: 1.12 | D4: Under P(X ≤ linha) | E4: =SUMIF($A$15:$A$35,"<="&FLOOR($B$5,1),$B$15:$B$35) -> 0.89635585 | F4: ex.: gols no 1º tempo — contagem.py projetou 1,12 em Grêmio x Chape
A5: linha (X.5) | B5: 2.5 | D5: Over P(X ≥ linha) | E5: =1-SUMIF($A$15:$A$35,"<="&FLOOR($B$5,1),$B$15:$B$35) -> 0.10364415
A6: r — dispersão (vazio = Poisson) | D6: odd justa do Under | E6: =IFERROR(1/(SUMIF($A$15:$A$35,"<="&FLOOR($B$5,1),$B$15:$B$35)),"") -> 1.1156284 | F6: gols: vazio (Poisson). escanteios: ~171. cartões: ~29. Excel trunca r p/ inteiro.
A7: k — p/ P(exatamente k) | B7: 3 | D7: odd justa do Over | E7: =IFERROR(1/(1-(SUMIF($A$15:$A$35,"<="&FLOOR($B$5,1),$B$15:$B$35))),"") -> 9.6483981
A8: faixa: de | B8: 1 | D8: P(exatamente k) | E8: =SUMIF($A$15:$A$35,$B$7,$B$15:$B$35) -> 0.076399937 | F8: P(de ≤ X ≤ até) — a aposta de faixa, tipo '1-4 gols'
A9: faixa: até | B9: 4 | D9: P(faixa de ≤ X ≤ até) | E9: =SUMIFS($B$15:$B$35,$A$15:$A$35,">="&$B$8,$A$15:$A$35,"<="&$B$9) -> 0.66786798
A10: odd da casa no Under (opcional) | B10: 1.11 | D10: implícita da casa (Under) | E10: =IF(N($B$10)>0,1/$B$10,"") -> 0.9009009 | F10: pra medir sua discordância da casa
D11: gap: modelo − casa | E11: =IF(N($B$10)>0,(SUMIF($A$15:$A$35,"<="&FLOOR($B$5,1),$B$15:$B$35))-1/$B$10,"") -> -0.0045450491
A13: Distribuição P(X=k)
A14: k | B14: P(X=k) | C14: P(X≤k)
A15: 0 | B15: =IF(N($B$6)>0,NEGBINOMDIST(A15,$B$6,$B$6/($B$6+$B$4)),POISSON(A15,$B$4,FALSE)) -> 0.32627979 | C15: =SUM($B$15:B15) -> 0.32627979
A16: 1 | B16: =IF(N($B$6)>0,NEGBINOMDIST(A16,$B$6,$B$6/($B$6+$B$4)),POISSON(A16,$B$4,FALSE)) -> 0.36543337 | C16: =SUM($B$15:B16) -> 0.69171316
A17: 2 | B17: =IF(N($B$6)>0,NEGBINOMDIST(A17,$B$6,$B$6/($B$6+$B$4)),POISSON(A17,$B$4,FALSE)) -> 0.20464269 | C17: =SUM($B$15:B17) -> 0.89635585
A18: 3 | B18: =IF(N($B$6)>0,NEGBINOMDIST(A18,$B$6,$B$6/($B$6+$B$4)),POISSON(A18,$B$4,FALSE)) -> 0.076399937 | C18: =SUM($B$15:B18) -> 0.97275579
A19: 4 | B19: =IF(N($B$6)>0,NEGBINOMDIST(A19,$B$6,$B$6/($B$6+$B$4)),POISSON(A19,$B$4,FALSE)) -> 0.021391982 | C19: =SUM($B$15:B19) -> 0.99414777
A20: 5 | B20: =IF(N($B$6)>0,NEGBINOMDIST(A20,$B$6,$B$6/($B$6+$B$4)),POISSON(A20,$B$4,FALSE)) -> 0.004791804 | C20: =SUM($B$15:B20) -> 0.99893957
A21: 6 | B21: =IF(N($B$6)>0,NEGBINOMDIST(A21,$B$6,$B$6/($B$6+$B$4)),POISSON(A21,$B$4,FALSE)) -> 0.00089447008 | C21: =SUM($B$15:B21) -> 0.99983404
A22: 7 | B22: =IF(N($B$6)>0,NEGBINOMDIST(A22,$B$6,$B$6/($B$6+$B$4)),POISSON(A22,$B$4,FALSE)) -> 0.00014311521 | C22: =SUM($B$15:B22) -> 0.99997716
A23: 8 | B23: =IF(N($B$6)>0,NEGBINOMDIST(A23,$B$6,$B$6/($B$6+$B$4)),POISSON(A23,$B$4,FALSE)) -> 2.003613e-05 | C23: =SUM($B$15:B23) -> 0.9999972
A24: 9 | B24: =IF(N($B$6)>0,NEGBINOMDIST(A24,$B$6,$B$6/($B$6+$B$4)),POISSON(A24,$B$4,FALSE)) -> 2.4933851e-06 | C24: =SUM($B$15:B24) -> 0.99999969
A25: 10 | B25: =IF(N($B$6)>0,NEGBINOMDIST(A25,$B$6,$B$6/($B$6+$B$4)),POISSON(A25,$B$4,FALSE)) -> 2.7925913e-07 | C25: =SUM($B$15:B25) -> 0.99999997
A26: 11 | B26: =IF(N($B$6)>0,NEGBINOMDIST(A26,$B$6,$B$6/($B$6+$B$4)),POISSON(A26,$B$4,FALSE)) -> 2.8433656e-08 | C26: =SUM($B$15:B26) -> 1
... A35: 20 | B35: =IF(N($B$6)>0,NEGBINOMDIST(A35,$B$6,$B$6/($B$6+$B$4)),POISSON(A35,$B$4,FALSE)) -> 1.2936775e-18 | C35: =SUM($B$15:B35) -> 1

Sheet Correlação
A1: CORRELAÇÃO ENTRE PERNAS (ρ dos indicadores 0/1)
A2: ρ > 0: a conjunta é MAIOR que o produto (multiplicar SUBESTIMA). ρ < 0: a conjunta é MENOR (multiplicar SUPERESTIMA — é onde se perde dinheiro achando que há valor).
A4: Par de mercados | B4: Mesmo jogo? | C4: ρ típico | D4: Status | E4: Nota
A5: Escanteios: lado casa × lado fora | B5: sim | C5: -0.219 | D5: MEDIDO (contagem.py) | E5: disputa o mesmo tempo de ataque; os desvios se cancelam no total
A6: Cartões: lado casa × lado fora | B6: sim | C6: 0.131 | D6: MEDIDO (contagem.py) | E6: fator comum à partida (árbitro, rivalidade) empurra os dois lados junto
A7: Faltas: lado casa × lado fora | B7: sim | C7: 0.138 | D7: MEDIDO (contagem.py) | E7: idem cartões
A8: Gols FT × Gols 1º tempo (mesmo jogo) | B8: sim | C8: 0.55 | D8: ILUSTRATIVO — MEDIR | E8: o 1º tempo é subconjunto do total; forte correlação positiva
A9: Under gols × Under escanteios (mesmo jogo) | B9: sim | C9: 0.15 | D9: ILUSTRATIVO — MEDIR | E9: jogo truncado derruba os dois
A10: Under gols × Under cartões (mesmo jogo) | B10: sim | C10: 0.1 | D10: ILUSTRATIVO — MEDIR | E10: jogo morno
A11: Under gols × Under chutes (mesmo jogo) | B11: sim | C11: 0.35 | D11: ILUSTRATIVO — MEDIR | E11: poucas finalizações → poucos gols
A12: Over gols × Under escanteios (mesmo jogo) | B12: sim | C12: -0.1 | D12: ILUSTRATIVO — MEDIR | E12: direções opostas
A13: Favorito não perde (DC) × Under gols | B13: sim | C13: 0.1 | D13: ILUSTRATIVO — MEDIR | E13: jogo controlado tende a ser fechado
A14: Total do time X × Total da partida | B14: sim | C14: 0.6 | D14: ILUSTRATIVO — MEDIR | E14: a perna é componente do todo
A15: Pernas de JOGOS DIFERENTES | B15: não | C15: 0 | D15: ILUSTRATIVO | E15: independência é boa aproximação; choque de rodada dá +0,03 a +0,08
A18: CALCULADORA DE PAR CORRELACIONADO
A19: P(A) | B19: 0.9
A20: P(B) | B20: 0.93
A21: ρ | B21: 0.1
A22: P(A e B) COM correlação | B22: =B19*B20+B21*SQRT(B19*(1-B19)*B20*(1-B20)) -> 0.84465441
A23: P(A e B) SEM correlação (produto) | B23: =B19*B20 -> 0.837
A24: diferença (quanto o produto erra) | B24: =B22-B23 -> 0.0076544105
A25: P(A ou B) | B25: =B19+B20-B22 -> 0.98534559
A26: limite inferior válido | B26: =MAX(0,B19+B20-1) -> 0.83
A27: limite superior válido | B27: =MIN(B19,B20) -> 0.9
A29: Uso: pra 2 pernas do MESMO jogo sem odd Criar Aposta. Com 3+ pernas ou pro número confiável, use o Simulador (core/gatekeeper.py). ρ medido é por LADO; pares de linha são chute — meça antes de confiar.

Sheet Parametros
A1: PARÂMETROS
A2: fração de Kelly | B2: 0.25 | C2: 1/4 é teto prudente — o edge é sempre incerto
A3: piso de odd oposta p/ de-vig | B3: 1.01 | C3: abaixo disso a planilha usa 1/odd cru
A4: λ — confiança no modelo | B4: 0.7 | C4: p̂ ajust. = q limpa + λ·(%Modelo − q limpa). 0 = usa o mercado, 1 = usa o modelo cru
A6: Stake do bilhete: no CABEÇALHO da aba Bilhete (célula H5), não aqui.

Sheet Glossário
A1: GLOSSÁRIO
A3: 1 bilhete = N jogos | B3: a planilha é UM bilhete (múltipla). Preencha 1 a 4 blocos JOGO conforme a estratégia. O Resumo combina os preenchidos.
A4: SGP / Criar Aposta | B4: Same Game Parlay — 2+ seleções do MESMO jogo numa odd combinada. A casa precifica a correlação; não é o produto das pernas.
A5: Odd Criar Aposta | B5: a odd combinada que a casa mostra pro bet builder de UM jogo. Vira o joint desse jogo (1/odd).
A6: %Modelo | B6: probabilidade que o modelo dá pra aquela SELEÇÃO acontecer. Para 'under 3.5' é P(sair MENOS de 3.5). Deve bater com 1/Odd Justa.
A7: q limpa (de-vig) | B7: implícita da casa SEM a margem (normalizada pela Odd Oposta). Sem Odd Oposta, cai pra 1/Odd Casa.
A8: impl. c/ margem | B8: 1 / Odd Casa — a probabilidade que o PREÇO da casa embute, AINDA COM a margem dentro. Sempre maior que "q limpa". A diferença entre as duas é o pedágio daquela perna. Coluna K, ao lado de p̂ ajust.
A9: margem linha | B9: 1/Odd Casa + 1/Odd Oposta − 1 — o overround (vig / "suco") só DESTA linha over/under. Mercado líquido ~3–6%; exótico 10–20%. Precisa da Odd Oposta preenchida. Coluna L.
A10: λ / p̂ ajust. | B10: λ (aba Parametros) encolhe o %Modelo pro mercado: p̂ ajust. = q limpa + λ·(%Modelo − q limpa). λ<1 desconta o otimismo do modelo.
A11: edge / edge ajust. | B11: p × Odd Casa − 1, com p usada (edge) ou p̂ ajust. (edge ajust.). Positivo NÃO garante valor.
A12: discord. / risco | B12: %Modelo − q limpa. ALTA se >10pp: o modelo erra mais onde mais discorda do mercado. NÃO é oportunidade.
A13: JOINT USADO | B13: probabilidade do jogo inteiro. Ordem: Simulador → 1/Odd Criar Aposta → produto dos %Modelo.
A14: Simulador | B14: Monte Carlo do jogo (core/gatekeeper.py): fração em que TODAS as pernas do jogo batem juntas.
... A19: Kelly | B19: fração da banca = edge / (odd−1). Assume o edge certo; use ≤ 1/4.
A22: DE-PARA P/ O TRACKER (colunas 'chave' e 'escopo/arg')
A23: chave (contagem) | B23: gols, gols_1t, escanteios, escanteios_1t, cartoes, cartoes_1t, chutes, chutes_gol, faltas, impedimentos, laterais, tiros_meta
A24: escopo (contagem) | B24: total | casa | fora | ambas (ambas = a planilha gera 2 pernas: casa≥linha E fora≥linha)
A25: linha / lado (contagem) | B25: vêm das colunas LINHA e SELEÇÃO da própria perna (ex.: 3.5 / under)
A26: chave (placar) | B26: resultado, dupla_chance, dnb, par_impar, time_marca, ambas_marcam, handicap_europeu, placar_exato, faixa_gols
A27: escopo/arg (placar) | B27: o parâmetro — resultado:home/draw/away · dupla_chance:1X/12/X2 · dnb:home/away · par_impar:True/False · time_marca:home/away · ambas_marcam:True/False · handicap_europeu:home:-1 · placar_exato:2:1 · faixa_gols:1:4
A28: perna sem chave | B28: fica de fora do tracker (não liquida). Preencha chave p/ ela entrar.

Sheet Listas
A1: Mercado (rótulo) | B1: escopo (contagem) | C1: chave interna | E1: escopo/arg p/ PLACAR
A2: Gols | B2: total | C2: gols | E2: CONTAGEM (Gols/Escanteios/... e _1t/_2t): escopo = total/casa/fora/ambas; linha+lado nas colunas B/C
A3: Gols 1º Tempo | B3: casa | C3: gols_1t | E3: resultado / resultado_1t / resultado_2t -> home / draw / away
A4: Gols 2º Tempo | B4: fora | C4: gols_2t | E4: dupla_chance (+_1t/_2t) -> 1X / 12 / X2
A5: Escanteios | B5: ambas | C5: escanteios | E5: dnb / dnb_2t -> home / away
A6: Escanteios 1º Tempo | C6: escanteios_1t | E6: ambas_marcam (+_1t/_2t) -> True / False
A7: Escanteios 2º Tempo | C7: escanteios_2t | E7: par_impar -> True (par) / False (ímpar) time_marca -> home / away
A8: Cartões | C8: cartoes | E8: handicap_europeu -> home:-1 handicap_asia -> home:-1.5 (.0 ou .5, sem .25/.75)
A9: Cartões 1º Tempo | C9: cartoes_1t | E9: placar_exato (+_1t) -> 2:1 faixa_gols -> 1:4
A10: Cartões 2º Tempo | C10: cartoes_2t | E10: Equipe com Mais X -> home / away / draw
A11: Cartões Vermelhos | C11: cartoes_vermelhos | E11: Handicap de X -> home:-2 / away:1 (linha inteira) Ímpar/Par de X -> par / impar
A12: Cartões Vermelhos 1º Tempo | C12: cartoes_vermelhos_1t | E12: Combo (E) -> sub-códigos com ';' ex.: resultado:home;over:2.5
A13: Cartões Vermelhos 2º Tempo | C13: cartoes_vermelhos_2t
A14: Finalizações | C14: chutes
A15: Finalizações 1º Tempo | C15: chutes_1t
A16: Finalizações 2º Tempo | C16: chutes_2t
A17: Finalizações no Gol | C17: chutes_gol
A18: Finalizações no Gol 1º Tempo | C18: chutes_gol_1t
A19: Finalizações no Gol 2º Tempo | C19: chutes_gol_2t
A20: Faltas | C20: faltas
A21: Faltas 1º Tempo | C21: faltas_1t
A22: Faltas 2º Tempo | C22: faltas_2t
A23: Impedimentos | C23: impedimentos
A24: Impedimentos 1º Tempo | C24: impedimentos_1t
... A62: Combo (E — vários mercados) | C62: combo
